test_can_get_user_from_email (tests.MyTests) ... ok
test_failed_test (tests.MyTests) ... FAIL
test_failed_test2 (tests.MyTests) ... FAIL
test_passed_test2 (tests.MyTests) ... ok

======================================================================
FAIL: test_failed_test (tests.MyTests)
----------------------------------------------------------------------
Traceback (most recent call last):
  File "/code/tests/__init__.py", line 32, in test_failed_test
    self.assertEqual(2, 4)
AssertionError: 2 != 4

======================================================================
FAIL: test_failed_test2 (tests.MyTests)
----------------------------------------------------------------------
Traceback (most recent call last):
  File "/code/tests/__init__.py", line 35, in test_failed_test2
    self.assertEqual(2, 4)
AssertionError: 2 != 4

----------------------------------------------------------------------
Ran 4 tests in 0.090s

FAILED (failures=2)
