test_can_get_user_from_email (tests.UserTests) ... ok
test_failed_test (tests.UserTests) ... FAIL
test_failed_test2 (tests.UserTests) ... FAIL
test_passed_test2 (tests.UserTests) ... FAIL

======================================================================
FAIL: test_failed_test (tests.UserTests)
----------------------------------------------------------------------
Traceback (most recent call last):
  File "/code/tests/__init__.py", line 32, in test_failed_test
    self.assertEqual(2, 8)
AssertionError: 2 != 8

======================================================================
FAIL: test_failed_test2 (tests.UserTests)
----------------------------------------------------------------------
Traceback (most recent call last):
  File "/code/tests/__init__.py", line 35, in test_failed_test2
    self.assertEqual(2, 4)
AssertionError: 2 != 4

======================================================================
FAIL: test_passed_test2 (tests.UserTests)
----------------------------------------------------------------------
Traceback (most recent call last):
  File "/code/tests/__init__.py", line 29, in test_passed_test2
    self.assertEqual(2, 5)
AssertionError: 2 != 5

----------------------------------------------------------------------
Ran 4 tests in 0.080s

FAILED (failures=3)
